2023-01-05 02:12:25,074 - instabot version: 0.117.0 (bot) - INFO - Instabot version: 0.117.0 Started
2023-01-05 02:12:25,076 - instabot version: 0.117.0 (bot) - DEBUG - Bot imported from C:\Users\bbf\AppData\Local\Programs\Python\Python311\Lib\site-packages\instabot\bot\bot.py
2023-01-05 02:12:25,080 - instabot version: 0.117.0 (api_login) - INFO - Not yet logged in starting: PRE-LOGIN FLOW!
2023-01-05 02:12:25,127 - instabot version: 0.117.0 (api) - WARNING - HTTPSConnectionPool(host='i.instagram.com', port=443): Max retries exceeded with url: /api/v1/accounts/get_prefill_candidates/ (Caused by NewConnectionError('<urllib3.connection.HTTPSConnection object at 0x0000026EBFC12BD0>: Failed to establish a new connection: [Errno 11002] getaddrinfo failed'))
2023-01-05 02:12:25,138 - instabot version: 0.117.0 (api) - WARNING - HTTPSConnectionPool(host='i.instagram.com', port=443): Max retries exceeded with url: /api/v1/qe/sync/ (Caused by NewConnectionError('<urllib3.connection.HTTPSConnection object at 0x0000026EBFC135D0>: Failed to establish a new connection: [Errno 11002] getaddrinfo failed'))
2023-01-05 02:12:25,149 - instabot version: 0.117.0 (api) - WARNING - HTTPSConnectionPool(host='i.instagram.com', port=443): Max retries exceeded with url: /api/v1/launcher/sync/ (Caused by NewConnectionError('<urllib3.connection.HTTPSConnection object at 0x0000026EBFC13CD0>: Failed to establish a new connection: [Errno 11002] getaddrinfo failed'))
2023-01-05 02:12:25,160 - instabot version: 0.117.0 (api) - WARNING - HTTPSConnectionPool(host='i.instagram.com', port=443): Max retries exceeded with url: /api/v1/accounts/contact_point_prefill/ (Caused by NewConnectionError('<urllib3.connection.HTTPSConnection object at 0x0000026EBFC1C390>: Failed to establish a new connection: [Errno 11002] getaddrinfo failed'))
